Workbook

Sheet README
A1: McLeod et al. (2022) Table II → 한국어 연역 후보 사전 (초안)
A3: 출처: McLeod, Sears, Chandler, Payne & Brigham (2022), Journal of Management Studies 59(7), Table II (pp.1671–1673). 원문 891개 중 890개 전사(PDF 줄바꿈으로 1개 차이 가능).
A4: 성격: 원 논문 절차 중 ② 연역 단계(Rodale 유의어)에 해당하는 '후보' 목록. 한국어 번역은 Claude 초안이며 확정 사전이 아님.
A5: 다음 단계: ③ DIPS 사업계획서 귀납 후보 추가 → ④ 평정자 3인 판정(Holsti ≥ .70) → ⑤ 외부 전문가 추가 제안 + 5인 만장일치.
A7: 시트 구성
A8: 후보사전_원어별: Table II 원어 1개당 한국어 후보 1행(후보가 여럿이면 여러 행). 평정자 판정 입력용.
A9: 고유키_요약: 형태소 매칭 키 기준으로 중복을 합친 목록. 실제 CATA 집계에 쓰일 사전의 모양.
A10: 집계: 차원별 후보 수·플래그 수·채택 수 (평정 입력에 따라 자동 갱신).
A12: 열 설명
A13: 형태소 분석: Kiwi(kiwipiepy) 분석 결과 전체. 매칭 키: 내용 형태소(NNG·VV·VA·XR 등)만 남긴 것 = 사업계획서에서 이 키와 일치하는 형태소를 셈.
A14: 예: '증가예정' → 증가/NNG + 예정/NNG 로 분석되므로 키 '증가/NNG'가 잡힘. '도와' → 돕/VV 로 원형 복원.
A15: 접두사(XPN)는 키에 포함: '비호감' = 비/XPN + 호감/NNG 이므로 '호감'(ethos)과 구별됨. 집계 시 긴 키(구 매칭)를 먼저 세고, 그 형태소는 짧은 키로 중복 집계하지 않음.
... A23: 입력 예시: 평정자1=유지, 평정자2=유지, 평정자3=제외, 비고='제조 맥락에서 logos' → 만장일치=제외

Sheet 후보사전_원어별
A1: No | B1: 차원 | C1: 테마(Table II) | D1: 원어(Table II) | E1: 한국어 후보 | F1: 형태소 분석(Kiwi) | G1: 매칭 키 | H1: 자동 플래그 | I1: 검토 메모 | J1: 평정자1 | K1: 평정자2 | L1: 평정자3 | M1: 만장일치 | N1: 비고
A2: 1 | B2: Logos(논리) | C2: logic | D2: logic | E2: 논리 | F2: 논리/NNG | G2: 논리/NNG | M2: =IF(COUNTA(J2:L2)<3,"",IF(COUNTIF(J2:L2,"유지")=3,"채택","제외"))
A3: 2 | B3: Logos(논리) | C3: logic | D3: reason | E3: 근거 | F3: 근거/NNG | G3: 근거/NNG | M3: =IF(COUNTA(J3:L3)<3,"",IF(COUNTIF(J3:L3,"유지")=3,"채택","제외"))
A4: 3 | B4: Logos(논리) | C4: logic | D4: reason | E4: 이유 | F4: 이유/NNG | G4: 이유/NNG | M4: =IF(COUNTA(J4:L4)<3,"",IF(COUNTIF(J4:L4,"유지")=3,"채택","제외"))
A5: 4 | B5: Logos(논리) | C5: logic | D5: judicious | E5: 신중 | F5: 신중/NNG | G5: 신중/NNG | H5: 차원충돌:ethos·logos·pathos | I5: logos(judicious)·pathos(cautious)·ethos(prudence, discreet)에 모두 대응 → 차원 배정 평정 필요 | M5: =IF(COUNTA(J5:L5)<3,"",IF(COUNTIF(J5:L5,"유지")=3,"채택","제외"))
A6: 5 | B6: Logos(논리) | C6: logic | D6: logistic | E6: 물류 | F6: 물류/NNG | G6: 물류/NNG | M6: =IF(COUNTA(J6:L6)<3,"",IF(COUNTIF(J6:L6,"유지")=3,"채택","제외"))
A7: 6 | B7: Logos(논리) | C7: logic | D7: politic | E7: 타당 | F7: 타당/NNG | G7: 타당/NNG | M7: =IF(COUNTA(J7:L7)<3,"",IF(COUNTIF(J7:L7,"유지")=3,"채택","제외"))
A8: 7 | B8: Logos(논리) | C8: logic | D8: astute | E8: 예리 | F8: 예리/NNP | G8: 예리/NNP | H8: 차원충돌:ethos·logos | M8: =IF(COUNTA(J8:L8)<3,"",IF(COUNTIF(J8:L8,"유지")=3,"채택","제외"))
A9: 8 | B9: Logos(논리) | C9: logic | D9: infer | E9: 추론 | F9: 추론/NNG | G9: 추론/NNG | M9: =IF(COUNTA(J9:L9)<3,"",IF(COUNTIF(J9:L9,"유지")=3,"채택","제외"))
A10: 9 | B10: Logos(논리) | C10: logic | D10: cogent | E10: 설득력 | F10: 설득력/NNG | G10: 설득력/NNG | M10: =IF(COUNTA(J10:L10)<3,"",IF(COUNTIF(J10:L10,"유지")=3,"채택","제외"))
A11: 10 | B11: Logos(논리) | C11: logic | D11: synthesis | E11: 종합 | F11: 종합/NNG | G11: 종합/NNG | M11: =IF(COUNTA(J11:L11)<3,"",IF(COUNTIF(J11:L11,"유지")=3,"채택","제외"))
A12: 11 | B12: Logos(논리) | C12: logic | D12: sane | E12: 건전 | F12: 건전/NNG | G12: 건전/NNG | H12: 차원충돌:ethos·logos | I12: logos(sane)·ethos(wholesome) 양쪽; '재무 건전성'은 logos | M12: =IF(COUNTA(J12:L12)<3,"",IF(COUNTIF(J12:L12,"유지")=3,"채택","제외"))
A13: 12 | B13: Logos(논리) | C13: logic | D13: sound-judgment | E13: 건전한 판단 | F13: 건전/NNG + 하/XSA + ᆫ/ETM + 판단/NNG | G13: 건전/NNG + 판단/NNG | H13: 구(句) 매칭 | M13: =IF(COUNTA(J13:L13)<3,"",IF(COUNTIF(J13:L13,"유지")=3,"채택","제외"))
A14: 13 | B14: Logos(논리) | C14: logic | D14: good-sense | E14: 양식 | F14: 양식/NNG | G14: 양식/NNG | M14: =IF(COUNTA(J14:L14)<3,"",IF(COUNTIF(J14:L14,"유지")=3,"채택","제외"))
A15: 14 | B15: Logos(논리) | C15: logic | D15: sober | E15: 냉철 | F15: 냉철/XR | G15: 냉철/XR | M15: =IF(COUNTA(J15:L15)<3,"",IF(COUNTIF(J15:L15,"유지")=3,"채택","제외"))
A16: 15 | B16: Logos(논리) | C16: logic | D16: presence-of-mind | E16: 침착 | F16: 침착/NNG | G16: 침착/NNG | M16: =IF(COUNTA(J16:L16)<3,"",IF(COUNTIF(J16:L16,"유지")=3,"채택","제외"))
A17: 16 | B17: Logos(논리) | C17: logic | D17: analytic | E17: 분석 | F17: 분석/NNG | G17: 분석/NNG | H17: 차원내 중복 | M17: =IF(COUNTA(J17:L17)<3,"",IF(COUNTIF(J17:L17,"유지")=3,"채택","제외"))
A18: 17 | B18: Logos(논리) | C18: logic | D18: common-sense | E18: 상식 | F18: 상식/NNG | G18: 상식/NNG | M18: =IF(COUNTA(J18:L18)<3,"",IF(COUNTIF(J18:L18,"유지")=3,"채택","제외"))
A19: 18 | B19: Logos(논리) | C19: logic | D19: deductive | E19: 연역 | F19: 연역/NNG | G19: 연역/NNG | M19: =IF(COUNTA(J19:L19)<3,"",IF(COUNTIF(J19:L19,"유지")=3,"채택","제외"))
A20: 19 | B20: Logos(논리) | C20: logic | D20: inductive | E20: 귀납 | F20: 귀납/NNG | G20: 귀납/NNG | M20: =IF(COUNTA(J20:L20)<3,"",IF(COUNTIF(J20:L20,"유지")=3,"채택","제외"))
A21: 20 | B21: Logos(논리) | C21: logic | D21: consequence | E21: 결과 | F21: 결과/NNG | G21: 결과/NNG | M21: =IF(COUNTA(J21:L21)<3,"",IF(COUNTIF(J21:L21,"유지")=3,"채택","제외"))
A22: 21 | B22: Logos(논리) | C22: logic | D22: rational | E22: 합리 | F22: 합리/NNG | G22: 합리/NNG | M22: =IF(COUNTA(J22:L22)<3,"",IF(COUNTIF(J22:L22,"유지")=3,"채택","제외"))
A23: 22 | B23: Logos(논리) | C23: logic | D23: practical | E23: 실용 | F23: 실용/NNG | G23: 실용/NNG | H23: 차원내 중복 | M23: =IF(COUNTA(J23:L23)<3,"",IF(COUNTIF(J23:L23,"유지")=3,"채택","제외"))
A24: 23 | B24: Logos(논리) | C24: logic | D24: practical | E24: 실질 | F24: 실질/NNG | G24: 실질/NNG | H24: 차원내 중복 | M24: =IF(COUNTA(J24:L24)<3,"",IF(COUNTIF(J24:L24,"유지")=3,"채택","제외"))
A25: 24 | B25: Logos(논리) | C25: logic | D25: pragmatic | E25: 실용적 | F25: 실용/NNG + 적/XSN | G25: 실용/NNG | H25: 차원내 중복 | M25: =IF(COUNTA(J25:L25)<3,"",IF(COUNTIF(J25:L25,"유지")=3,"채택","제외"))
A26: 25 | B26: Logos(논리) | C26: logic | D26: sensible | E26: 합당 | F26: 합당/NNG | G26: 합당/NNG | M26: =IF(COUNTA(J26:L26)<3,"",IF(COUNTIF(J26:L26,"유지")=3,"채택","제외"))
A27: 26 | B27: Logos(논리) | C27: logic | D27: advisable | E27: 바람직 | F27: 바람직/XR | G27: 바람직/XR | M27: =IF(COUNTA(J27:L27)<3,"",IF(COUNTIF(J27:L27,"유지")=3,"채택","제외"))
A28: 27 | B28: Logos(논리) | C28: logic | D28: well-advised | E28: 적절한 판단 | F28: 적절/XR + 하/XSA + ᆫ/ETM + 판단/NNG | G28: 적절/XR + 판단/NNG | H28: 구(句) 매칭 | M28: =IF(COUNTA(J28:L28)<3,"",IF(COUNTIF(J28:L28,"유지")=3,"채택","제외"))
A29: 28 | B29: Logos(논리) | C29: logic | D29: well-argued | E29: 논거 | F29: 논거/NNG | G29: 논거/NNG | M29: =IF(COUNTA(J29:L29)<3,"",IF(COUNTIF(J29:L29,"유지")=3,"채택","제외"))
A30: 29 | B30: Logos(논리) | C30: logic | D30: well-grounded | E30: 근거 탄탄 | F30: 근거/NNG + 탄탄/XR | G30: 근거/NNG + 탄탄/XR | H30: 구(句) 매칭 | M30: =IF(COUNTA(J30:L30)<3,"",IF(COUNTIF(J30:L30,"유지")=3,"채택","제외"))
A31: 30 | B31: Logos(논리) | C31: logic | D31: well-founded | E31: 근거 있는 | F31: 근거/NNG + 있/VA + 는/ETM | G31: 근거/NNG + 있/VA | H31: 구(句) 매칭 | M31: =IF(COUNTA(J31:L31)<3,"",IF(COUNTIF(J31:L31,"유지")=3,"채택","제외"))
A32: 31 | B32: Logos(논리) | C32: logic | D32: plausible | E32: 타당성 | F32: 타당성/NNG | G32: 타당성/NNG | M32: =IF(COUNTA(J32:L32)<3,"",IF(COUNTIF(J32:L32,"유지")=3,"채택","제외"))
A33: 32 | B33: Logos(논리) | C33: efficiency | D33: efficiency | E33: 효율 | F33: 효율/NNG | G33: 효율/NNG | M33: =IF(COUNTA(J33:L33)<3,"",IF(COUNTIF(J33:L33,"유지")=3,"채택","제외"))
A34: 33 | B34: Logos(논리) | C34: efficiency | D34: yield | E34: 수율 | F34: 수율/NNG | G34: 수율/NNG | I34: yield. 제조업 핵심 지표 → logos | M34: =IF(COUNTA(J34:L34)<3,"",IF(COUNTIF(J34:L34,"유지")=3,"채택","제외"))
A35: 34 | B35: Logos(논리) | C35: efficiency | D35: yield | E35: 수익률 | F35: 수익/NNG + 률/XSN | G35: 수익/NNG | H35: 차원내 중복 | M35: =IF(COUNTA(J35:L35)<3,"",IF(COUNTIF(J35:L35,"유지")=3,"채택","제외"))
A36: 35 | B36: Logos(논리) | C36: efficiency | D36: minimum | E36: 최소 | F36: 최소/NNG | G36: 최소/NNG | M36: =IF(COUNTA(J36:L36)<3,"",IF(COUNTIF(J36:L36,"유지")=3,"채택","제외"))
A37: 36 | B37: Logos(논리) | C37: efficiency | D37: maximum | E37: 최대 | F37: 최대/NNG | G37: 최대/NNG | M37: =IF(COUNTA(J37:L37)<3,"",IF(COUNTIF(J37:L37,"유지")=3,"채택","제외"))
A38: 37 | B38: Logos(논리) | C38: efficiency | D38: bargain | E38: 저가 | F38: 저가/NNG | G38: 저가/NNG | M38: =IF(COUNTA(J38:L38)<3,"",IF(COUNTIF(J38:L38,"유지")=3,"채택","제외"))
A39: 38 | B39: Logos(논리) | C39: efficiency | D39: rate | E39: 비율 | F39: 비율/NNG | G39: 비율/NNG | M39: =IF(COUNTA(J39:L39)<3,"",IF(COUNTIF(J39:L39,"유지")=3,"채택","제외"))
A40: 39 | B40: Logos(논리) | C40: efficiency | D40: stabilize | E40: 안정화 | F40: 안정/NNG + 화/XSN | G40: 안정/NNG | M40: =IF(COUNTA(J40:L40)<3,"",IF(COUNTIF(J40:L40,"유지")=3,"채택","제외"))
...

Sheet 고유키_요약
A1: 차원 | B1: 매칭 키 | C1: 한국어 표기 | D1: 원어 수 | E1: 원어(Table II) | F1: 자동 플래그 | G1: 검토 메모
A2: Logos(논리) | B2: 1/SN + 인/NNG | C2: 1인당 | D2: 1 | E2: capita | F2: 구(句) 매칭
A3: Logos(논리) | B3: EBITDA/SL | C3: EBITDA | D3: 1 | E3: EBITDA
A4: Logos(논리) | B4: 가격/NNG | C4: 가격 | D4: 1 | E4: price
A5: Logos(논리) | B5: 가동/NNG | C5: 가동 | D5: 1 | E5: operate
A6: Logos(논리) | B6: 가이드/NNG | C6: 가이드 | D6: 1 | E6: guide
A7: Logos(논리) | B7: 가치/NNG | C7: 가치 | D7: 1 | E7: valuable | F7: 차원충돌:ethos·logos | G7: logos(valuable)·ethos(worthy) 양쪽; '가치사슬' 등 과잉매칭
A8: Logos(논리) | B8: 가치/NNG + 있/VV | C8: 가치 있는 | D8: 1 | E8: worthwhile | F8: 구(句) 매칭
A9: Logos(논리) | B9: 감소/NNG | C9: 감소 | D9: 1 | E9: reduce
A10: Logos(논리) | B10: 개발/NNG | C10: 개발 | D10: 1 | E10: develop
A11: Logos(논리) | B11: 개선/NNG | C11: 개선 | D11: 1 | E11: improve
A12: Logos(논리) | B12: 개연/NNG | C12: 개연성 | D12: 1 | E12: probable
A13: Logos(논리) | B13: 객관/NNG | C13: 객관 | D13: 1 | E13: objective
A14: Logos(논리) | B14: 거래/NNG | C14: 거래 | D14: 2 | E14: transaction, deal | F14: 차원내 중복
A15: Logos(논리) | B15: 거래소/NNG | C15: 거래소 | D15: 1 | E15: exchange
A16: Logos(논리) | B16: 건전/NNG | C16: 건전 | D16: 1 | E16: sane | F16: 차원충돌:ethos·logos | G16: logos(sane)·ethos(wholesome) 양쪽; '재무 건전성'은 logos
A17: Logos(논리) | B17: 건전/NNG + 판단/NNG | C17: 건전한 판단 | D17: 1 | E17: sound-judgment | F17: 구(句) 매칭
A18: Logos(논리) | B18: 검증/NNG | C18: 검증 | D18: 1 | E18: verifiable
A19: Logos(논리) | B19: 결과/NNG | C19: 결과 | D19: 1 | E19: consequence
A20: Logos(논리) | B20: 결실/NNG | C20: 결실 | D20: 1 | E20: fruitful
A21: Logos(논리) | B21: 결함/NNG | C21: 결함 | D21: 1 | E21: deficiency
A22: Logos(논리) | B22: 경제/NNG | C22: 경제 | D22: 1 | E22: economic
A23: Logos(논리) | B23: 계약/NNG | C23: 계약 | D23: 1 | E23: contract
A24: Logos(논리) | B24: 계정/NNG | C24: 계정 | D24: 1 | E24: account
A25: Logos(논리) | B25: 계획/NNG | C25: 계획 | D25: 1 | E25: plan
A26: Logos(논리) | B26: 고/XPN + 수익/NNG | C26: 고수익 | D26: 2 | E26: lucrative, well-paying | F26: 구(句) 매칭, 차원내 중복
A27: Logos(논리) | B27: 고도/NNG | C27: 고도화 | D27: 1 | E27: advance | G27: advance. 한국 사업계획서 특유 빈출어 → logos
A28: Logos(논리) | B28: 고정/NNG | C28: 고정 | D28: 1 | E28: fix
A29: Logos(논리) | B29: 공급/NNG | C29: 공급 | D29: 1 | E29: supply
A30: Logos(논리) | B30: 공식/NNG | C30: 공식 | D30: 1 | E30: formula
A31: Logos(논리) | B31: 공정/NNG | C31: 공정 | D31: 1 | E31: process | F31: 차원충돌:ethos·logos | G31: 동음이의: 工程(제조 공정=logos) vs 公正(공정하다=ethos). '공정+하(XSA)'면 公正으로 분리 가능
A32: Logos(논리) | B32: 공학/NNG | C32: 공학 | D32: 1 | E32: engineering
A33: Logos(논리) | B33: 과학/NNG | C33: 과학 | D33: 1 | E33: scientific
A34: Logos(논리) | B34: 관심/NNG | C34: 관심 | D34: 1 | E34: interest | G34: interest(logos/scientific) 번역 중 '관심'은 오히려 정서적 → '이자'만 유지 고려
A35: Logos(논리) | B35: 관찰/NNG | C35: 관찰 | D35: 1 | E35: observe
A36: Logos(논리) | B36: 관행/NNG | C36: 관행 | D36: 1 | E36: practice
A37: Logos(논리) | B37: 교육/NNG | C37: 교육 | D37: 1 | E37: educate
A38: Logos(논리) | B38: 교환/NNG | C38: 교환 | D38: 1 | E38: exchange
A39: Logos(논리) | B39: 구매/NNG | C39: 구매 | D39: 1 | E39: purchase
A40: Logos(논리) | B40: 구조/NNG | C40: 구조 | D40: 1 | E40: structure
...

Sheet 집계
A1: 차원 | B1: Table II 원어 수 | C1: 한국어 후보 행 수 | D1: 고유 매칭 키 수 | E1: 플래그·메모 있는 행 | F1: 평정 완료 행 | G1: 채택(만장일치)
A2: Logos(논리) | B2: 301 | C2: =COUNTIF(후보사전_원어별!$B$2:$B$963,A2) -> 340 | D2: =COUNTIF(고유키_요약!$A$2:$A$815,A2) -> 318 | E2: =COUNTIFS(후보사전_원어별!$B$2:$B$963,A2,후보사전_원어별!$H$2:$H$963,"?*")+COUNTIFS(후보사전_원어별!$B$2:$B$963,A2,후보사전_원어별!$H$2:$H$963,"",후보사전_원어별!$I$2:$I$963,"?*") -> 80 | F2: =COUNTIFS(후보사전_원어별!$B$2:$B$963,A2,후보사전_원어별!$M$2:$M$963,"채택")+COUNTIFS(후보사전_원어별!$B$2:$B$963,A2,후보사전_원어별!$M$2:$M$963,"제외") -> 0 | G2: =COUNTIFS(후보사전_원어별!$B$2:$B$963,A2,후보사전_원어별!$M$2:$M$963,"채택") -> 0
A3: Pathos(감정) | B3: 327 | C3: =COUNTIF(후보사전_원어별!$B$2:$B$963,A3) -> 340 | D3: =COUNTIF(고유키_요약!$A$2:$A$815,A3) -> 268 | E3: =COUNTIFS(후보사전_원어별!$B$2:$B$963,A3,후보사전_원어별!$H$2:$H$963,"?*")+COUNTIFS(후보사전_원어별!$B$2:$B$963,A3,후보사전_원어별!$H$2:$H$963,"",후보사전_원어별!$I$2:$I$963,"?*") -> 152 | F3: =COUNTIFS(후보사전_원어별!$B$2:$B$963,A3,후보사전_원어별!$M$2:$M$963,"채택")+COUNTIFS(후보사전_원어별!$B$2:$B$963,A3,후보사전_원어별!$M$2:$M$963,"제외") -> 0 | G3: =COUNTIFS(후보사전_원어별!$B$2:$B$963,A3,후보사전_원어별!$M$2:$M$963,"채택") -> 0
A4: Ethos(성품) | B4: 262 | C4: =COUNTIF(후보사전_원어별!$B$2:$B$963,A4) -> 282 | D4: =COUNTIF(고유키_요약!$A$2:$A$815,A4) -> 228 | E4: =COUNTIFS(후보사전_원어별!$B$2:$B$963,A4,후보사전_원어별!$H$2:$H$963,"?*")+COUNTIFS(후보사전_원어별!$B$2:$B$963,A4,후보사전_원어별!$H$2:$H$963,"",후보사전_원어별!$I$2:$I$963,"?*") -> 131 | F4: =COUNTIFS(후보사전_원어별!$B$2:$B$963,A4,후보사전_원어별!$M$2:$M$963,"채택")+COUNTIFS(후보사전_원어별!$B$2:$B$963,A4,후보사전_원어별!$M$2:$M$963,"제외") -> 0 | G4: =COUNTIFS(후보사전_원어별!$B$2:$B$963,A4,후보사전_원어별!$M$2:$M$963,"채택") -> 0
A5: 합계 | B5: =SUM(B2:B4) -> 890 | C5: =SUM(C2:C4) -> 962 | D5: =SUM(D2:D4) -> 814 | E5: =SUM(E2:E4) -> 363 | F5: =SUM(F2:F4) -> 0 | G5: =SUM(G2:G4) -> 0
A7: Table II 원어 수는 원문에서 전사한 값(하드코딩; 원문 보고치 891).
